.....F..E.
======================================================================
ERROR: test_unknown_action1 (__main__.AuthTestCase)
----------------------------------------------------------------------
Traceback (most recent call last):
  File "tester.py", line 97, in test_unknown_action1
    "password": "pass"
  File "tester.py", line 6, in send
    resp = test.app.post('/', data=query)
  File "C:\Python27\lib\site-packages\werkzeug-0.9.4-py2.7.egg\werkzeug\test.py", line 771, in post
    return self.open(*args, **kw)
  File "C:\Python27\lib\site-packages\flask-0.10.1-py2.7.egg\flask\testing.py", line 108, in open
    follow_redirects=follow_redirects)
  File "C:\Python27\lib\site-packages\werkzeug-0.9.4-py2.7.egg\werkzeug\test.py", line 735, in open
    response = self.run_wsgi_app(environ, buffered=buffered)
  File "C:\Python27\lib\site-packages\werkzeug-0.9.4-py2.7.egg\werkzeug\test.py", line 658, in run_wsgi_app
    rv = run_wsgi_app(self.application, environ, buffered=buffered)
  File "C:\Python27\lib\site-packages\werkzeug-0.9.4-py2.7.egg\werkzeug\test.py", line 854, in run_wsgi_app
    app_iter = app(environ, start_response)
  File "C:\Python27\lib\site-packages\flask-0.10.1-py2.7.egg\flask\app.py", line 1836, in __call__
    return self.wsgi_app(environ, start_response)
  File "C:\Python27\lib\site-packages\flask-0.10.1-py2.7.egg\flask\app.py", line 1820, in wsgi_app
    response = self.make_response(self.handle_exception(e))
  File "C:\Python27\lib\site-packages\flask-0.10.1-py2.7.egg\flask\app.py", line 1403, in handle_exception
    reraise(exc_type, exc_value, tb)
  File "C:\Python27\lib\site-packages\flask-0.10.1-py2.7.egg\flask\app.py", line 1817, in wsgi_app
    response = self.full_dispatch_request()
  File "C:\Python27\lib\site-packages\flask-0.10.1-py2.7.egg\flask\app.py", line 1477, in full_dispatch_request
    rv = self.handle_user_exception(e)
  File "C:\Python27\lib\site-packages\flask-0.10.1-py2.7.egg\flask\app.py", line 1381, in handle_user_exception
    reraise(exc_type, exc_value, tb)
  File "C:\Python27\lib\site-packages\flask-0.10.1-py2.7.egg\flask\app.py", line 1475, in full_dispatch_request
    rv = self.dispatch_request()
  File "C:\Python27\lib\site-packages\flask-0.10.1-py2.7.egg\flask\app.py", line 1461, in dispatch_request
    return self.view_functions[rule.endpoint](**req.view_args)
  File "C:\web\game\run.py", line 16, in index
    return p.process(req)
  File "C:\web\game\process.py", line 35, in process
    if not req['action'] or not req['params']:
KeyError: 'action'

======================================================================
FAIL: test_signup_bad_login2 (__main__.AuthTestCase)
----------------------------------------------------------------------
Traceback (most recent call last):
  File "tester.py", line 145, in test_signup_bad_login2
    assert resp == { "result": "badLogin" }, resp
AssertionError: {u'result': u'ok'}

----------------------------------------------------------------------
Ran 10 tests in 1.700s

FAILED (failures=1, errors=1)
