........F.
======================================================================
FAIL: test_unknown_action1 (__main__.AuthTestCase)
----------------------------------------------------------------------
Traceback (most recent call last):
  File "tester.py", line 85, in test_unknown_action1
    assert resp == { "result": "unknowwwnAction" }, resp
AssertionError: {u'result': u'unknownAction'}

----------------------------------------------------------------------
Ran 10 tests in 1.219s

FAILED (failures=1)
